Workbook

Sheet Les meg
B1: Nøkkeltalsanalyse jordbruk – produksjonsvis oppsett
B3: Føremål | C3: Arbeidsboka deler jordbruksanalysen opp i éin fane per produksjon (korn, silofôr, høy, potet, agurk, tomat, frilandsgrønsaker, gulrot, kålrot, mjølk, oksar, mellomkalv, ammekyr, smågris, purkering, slaktegris, sau, geit, egg og slaktekylling) pluss fellesark for grovfôr, faste kostnader og totaløkonomi. Oppsettet byggjer på den vedlagde analysen «Analyse 2025» (Duett-import) og kontoplanen frå Tripletex.
B5: Oppbygging av kvar fane | C5: 1. INPUT – produksjonsdata → 2. INPUT – rekneskapstal (kr) → 3. fordelte faste kostnader (lenkje) → 4. UTREKNING totalt → 5. OUTPUT per eining → 6. OUTPUT nøkkeltal. Kolonne E forklarar kvar formel i ord med cellereferansar, kolonne F viser sjølve Excel-formelen.
B7: Fargekodar | C7: Blå tal på gul botn = input som skal fyllast inn. Svart = formel. Grøn = lenkje frå eit anna ark. Nøkkeltal er utheva.
B9: Forteikn | C9: Alle inntekter og kostnader blir lagt inn som positive kronebeløp. Beholdningsendring buskap/ferdigvarer: + = auke i lager (inntekt). «Endring eigenprodusert grovfôr» følgjer kostnadsforteikn: + = nedgang i lager (kostnad).
B11: Med i totalen | C11: På fana «Oversikt» set du J/N for kvar produksjon. Berre produksjonar med J blir tekne med i Grovfôr og Totaløkonomi. Eksempeltala for silofôr, ammekyr og sau, grovfôrareal og faste kostnader er henta frå vedlagt analyse 2025, så nøkkeltala kan kontrollerast mot den (t.d. DB pr vf. sau u/tilskot = 315 kr). Dei andre produksjonane har fiktive, realistiske eksempeltal og står som N.
B13: Analysegrupper | C13: Eksempelanalysen har eigne ark for Mjølk <80 % / 80–120 % / >120 % påsett, Ammekyr <50 % / >50 % og Smågris / Gris kombinert. Her ligg dette som nøkkeltalet «Analysegruppe» på kvar fane, rekna ut frå påsett- eller framfôringsprosenten.
B15: Grovfôr | C15: Fana «Grovfôr» reknar korrigert grovfôrareal (overflatedyrka/1,25 + fulldyrka + kulturbeite/2,5), «kueiningar», variabel grovfôrkostnad pr dekar og maskinkostnad pr dekar. DB pr dekar grovfôr på kvar husdyrfane fordeler arealet etter produksjonen sin del av eigen grovfôrkostnad – same metode som eksempelanalysen.
B17: Kopling til Tripletex | C17: Fana «Kontokopling» viser kva Tripletex-kontoar (jordbrukskontoplanen i Tripletex) som blir summert til kvar post, og kva produksjon ein konto høyrer til. Same kopling blir brukt i HTML-appen (app/analyse.html).
B19: Kueiningar og vekter | C19: Vektene for «kueiningar» følgjer eksempelanalysen: mjølk/oksar: kyr = 1, ungdyr over 12 md = 1/4, under 12 md = 1/8; ammekyr: ungdyr over 12 md = 1/3, under 12 md = 1/4; sau: sum dyretal / 6; geit: sum vaksne geiter / 7. Alle snitt av 1.1. og 31.12.
B21: Ikkje med | C21: Marginalanalysane i eksempelfila (Mjølk marginal, Okse marginal, Ammekyr marginal, Marginal sau/geit) krev tilskotssatsar og er ikkje bygde om her.
B23: Faner
B24: Faste kostnader | C24: Maskin-, bygnings- og andre faste kostnader. Maskinkostnader og innandørsmekanisering blir fordelt på produksjonane.
B25: Grovfôr | C25: Felles grovfôrgrunnlag for mjølk, oksar, mellomkalv, ammekyr, sau og geit.
B26: Totaløkonomi | C26: Summerer dekningsbidraget frå alle produksjonar som er med, trekkjer frå faste kostnader og avstemmer mot skattemessig resultat.
B27: Korn | C27: Korn til modning (driftsgrein 1100–1190).
B28: Silofor | C28: Areal der graset blir selt som silofôr/rundballar (driftsgrein 1522–1523). Eksempeltal frå vedlagt analyse 2025.
B29: Høy | C29: Areal der graset blir selt som høy (driftsgrein 1510–1513).
B30: Potet | C30: Matpotet og settepotet (driftsgrein 2100–2130).
B31: Agurk | C31: Veksthusagurk (driftsgrein 3300–3330). Nøkkeltal pr m².
B32: Tomat | C32: Veksthustomat (driftsgrein 3400–3490). Nøkkeltal pr m².
B33: Frilandsgrønsak | C33: Frilandsgrønsaker utanom gulrot og kålrot.
B34: Gulrot | C34: Gulrot (driftsgrein 2500–2590).
B35: Kålrot | C35: Kålrot (driftsgrein 2280–2282).
... B46: Slaktekylling | C46: Slaktekylling (driftsgrein 6510–6511).

Sheet Oversikt
A1: Oversikt over alle produksjonar
A2: Summert frå kvar produksjonsfane. Set J i kolonne B for produksjonar som skal vere med i grovfôr- og totaløkonomien.
A3: Fargekodar: blå tal på gul botn = input (skal fyllast inn) · svart = formel · grøn = lenkje frå anna ark. Alle kronebeløp er positive (inntekt og kostnad).
A6: Produksjon | B6: Med i totalen (J/N) | C6: Eining | D6: Tal einingar | E6: Produksjons- inntekter | F6: Variable kostnader | G6: DB u/tilskot | H6: Tilskot | I6: DB m/tilskot | J6: DB u/tilskot pr eining | K6: DB m/tilskot pr eining | L6: DB m/tilskot etter maskin og innandørsmek.
A7: Korn | B7: N | C7: dekar | D7: =Korn!C7 | E7: =Korn!C24 | F7: =Korn!C25 | G7: =Korn!C26 | H7: =Korn!C11 | I7: =Korn!C27 | J7: =IF(Korn!C7=0,0,Korn!C26/Korn!C7) | K7: =IF(Korn!C7=0,0,Korn!C27/Korn!C7) | L7: =Korn!C28
A8: Silofor | B8: J | C8: dekar | D8: =Silofor!C7 | E8: =Silofor!C25 | F8: =Silofor!C26 | G8: =Silofor!C27 | H8: =Silofor!C13 | I8: =Silofor!C28 | J8: =IF(Silofor!C7=0,0,Silofor!C27/Silofor!C7) | K8: =IF(Silofor!C7=0,0,Silofor!C28/Silofor!C7) | L8: =Silofor!C29
A9: Høy | B9: N | C9: dekar | D9: ='Høy'!C7 | E9: ='Høy'!C23 | F9: ='Høy'!C24 | G9: ='Høy'!C25 | H9: ='Høy'!C11 | I9: ='Høy'!C26 | J9: =IF('Høy'!C7=0,0,'Høy'!C25/'Høy'!C7) | K9: =IF('Høy'!C7=0,0,'Høy'!C26/'Høy'!C7) | L9: ='Høy'!C27
A10: Potet | B10: N | C10: dekar | D10: =Potet!C7 | E10: =Potet!C24 | F10: =Potet!C25 | G10: =Potet!C26 | H10: =Potet!C11 | I10: =Potet!C27 | J10: =IF(Potet!C7=0,0,Potet!C26/Potet!C7) | K10: =IF(Potet!C7=0,0,Potet!C27/Potet!C7) | L10: =Potet!C28
A11: Agurk | B11: N | C11: m² | D11: =Agurk!C7 | E11: =Agurk!C25 | F11: =Agurk!C26 | G11: =Agurk!C27 | H11: =Agurk!C11 | I11: =Agurk!C28 | J11: =IF(Agurk!C7=0,0,Agurk!C27/Agurk!C7) | K11: =IF(Agurk!C7=0,0,Agurk!C28/Agurk!C7) | L11: =Agurk!C29
A12: Tomat | B12: N | C12: m² | D12: =Tomat!C7 | E12: =Tomat!C25 | F12: =Tomat!C26 | G12: =Tomat!C27 | H12: =Tomat!C11 | I12: =Tomat!C28 | J12: =IF(Tomat!C7=0,0,Tomat!C27/Tomat!C7) | K12: =IF(Tomat!C7=0,0,Tomat!C28/Tomat!C7) | L12: =Tomat!C29
A13: Frilandsgrønsak | B13: N | C13: dekar | D13: ='Frilandsgrønsak'!C7 | E13: ='Frilandsgrønsak'!C24 | F13: ='Frilandsgrønsak'!C25 | G13: ='Frilandsgrønsak'!C26 | H13: ='Frilandsgrønsak'!C11 | I13: ='Frilandsgrønsak'!C27 | J13: =IF('Frilandsgrønsak'!C7=0,0,'Frilandsgrønsak'!C26/'Frilandsgrønsak'!C7) | K13: =IF('Frilandsgrønsak'!C7=0,0,'Frilandsgrønsak'!C27/'Frilandsgrønsak'!C7) | L13: ='Frilandsgrønsak'!C28
A14: Gulrot | B14: N | C14: dekar | D14: =Gulrot!C7 | E14: =Gulrot!C24 | F14: =Gulrot!C25 | G14: =Gulrot!C26 | H14: =Gulrot!C11 | I14: =Gulrot!C27 | J14: =IF(Gulrot!C7=0,0,Gulrot!C26/Gulrot!C7) | K14: =IF(Gulrot!C7=0,0,Gulrot!C27/Gulrot!C7) | L14: =Gulrot!C28
A15: Kålrot | B15: N | C15: dekar | D15: ='Kålrot'!C7 | E15: ='Kålrot'!C24 | F15: ='Kålrot'!C25 | G15: ='Kålrot'!C26 | H15: ='Kålrot'!C11 | I15: ='Kålrot'!C27 | J15: =IF('Kålrot'!C7=0,0,'Kålrot'!C26/'Kålrot'!C7) | K15: =IF('Kålrot'!C7=0,0,'Kålrot'!C27/'Kålrot'!C7) | L15: ='Kålrot'!C28
A16: Mjølk | B16: N | C16: årskyr | D16: ='Mjølk'!C7 | E16: ='Mjølk'!C50 | F16: ='Mjølk'!C55 | G16: ='Mjølk'!C56 | H16: ='Mjølk'!C21 | I16: ='Mjølk'!C57 | J16: =IF('Mjølk'!C7=0,0,'Mjølk'!C56/'Mjølk'!C7) | K16: =IF('Mjølk'!C7=0,0,'Mjølk'!C57/'Mjølk'!C7) | L16: ='Mjølk'!C58
A17: Oksar | B17: N | C17: oksar | D17: =Oksar!C7 | E17: =Oksar!C47 | F17: =Oksar!C52 | G17: =Oksar!C53 | H17: =Oksar!C20 | I17: =Oksar!C54 | J17: =IF(Oksar!C7=0,0,Oksar!C53/Oksar!C7) | K17: =IF(Oksar!C7=0,0,Oksar!C54/Oksar!C7) | L17: =Oksar!C55
A18: Mellomkalv | B18: N | C18: kalvar | D18: =Mellomkalv!C7 | E18: =Mellomkalv!C47 | F18: =Mellomkalv!C52 | G18: =Mellomkalv!C53 | H18: =Mellomkalv!C20 | I18: =Mellomkalv!C54 | J18: =IF(Mellomkalv!C7=0,0,Mellomkalv!C53/Mellomkalv!C7) | K18: =IF(Mellomkalv!C7=0,0,Mellomkalv!C54/Mellomkalv!C7) | L18: =Mellomkalv!C55
A19: Ammekyr | B19: J | C19: ammekyr | D19: =Ammekyr!C7 | E19: =Ammekyr!C52 | F19: =Ammekyr!C57 | G19: =Ammekyr!C58 | H19: =Ammekyr!C25 | I19: =Ammekyr!C59 | J19: =IF(Ammekyr!C7=0,0,Ammekyr!C58/Ammekyr!C7) | K19: =IF(Ammekyr!C7=0,0,Ammekyr!C59/Ammekyr!C7) | L19: =Ammekyr!C60
A20: Smågris | B20: N | C20: årspurker | D20: ='Smågris'!C7 | E20: ='Smågris'!C32 | F20: ='Smågris'!C33 | G20: ='Smågris'!C34 | H20: ='Smågris'!C17 | I20: ='Smågris'!C35 | J20: =IF('Smågris'!C7=0,0,'Smågris'!C34/'Smågris'!C7) | K20: =IF('Smågris'!C7=0,0,'Smågris'!C35/'Smågris'!C7) | L20: ='Smågris'!C36
A21: Purkering | B21: N | C21: årspurker | D21: =Purkering!C7 | E21: =Purkering!C33 | F21: =Purkering!C34 | G21: =Purkering!C35 | H21: =Purkering!C17 | I21: =Purkering!C36 | J21: =IF(Purkering!C7=0,0,Purkering!C35/Purkering!C7) | K21: =IF(Purkering!C7=0,0,Purkering!C36/Purkering!C7) | L21: =Purkering!C37
A22: Slaktegris | B22: N | C22: slaktegris | D22: =Slaktegris!C7 | E22: =Slaktegris!C29 | F22: =Slaktegris!C30 | G22: =Slaktegris!C31 | H22: =Slaktegris!C16 | I22: =Slaktegris!C32 | J22: =IF(Slaktegris!C7=0,0,Slaktegris!C31/Slaktegris!C7) | K22: =IF(Slaktegris!C7=0,0,Slaktegris!C32/Slaktegris!C7) | L22: =Slaktegris!C33
A23: Sau | B23: J | C23: vf. sau | D23: =Sau!C7 | E23: =Sau!C58 | F23: =Sau!C63 | G23: =Sau!C64 | H23: =Sau!C29 | I23: =Sau!C65 | J23: =IF(Sau!C7=0,0,Sau!C64/Sau!C7) | K23: =IF(Sau!C7=0,0,Sau!C65/Sau!C7) | L23: =Sau!C66
A24: Geit | B24: N | C24: geiter | D24: =Geit!C7 | E24: =Geit!C46 | F24: =Geit!C51 | G24: =Geit!C52 | H24: =Geit!C18 | I24: =Geit!C53 | J24: =IF(Geit!C7=0,0,Geit!C52/Geit!C7) | K24: =IF(Geit!C7=0,0,Geit!C53/Geit!C7) | L24: =Geit!C54
A25: Egg | B25: N | C25: høner | D25: =Egg!C7 | E25: =Egg!C24 | F25: =Egg!C25 | G25: =Egg!C26 | H25: =Egg!C11 | I25: =Egg!C27 | J25: =IF(Egg!C7=0,0,Egg!C26/Egg!C7) | K25: =IF(Egg!C7=0,0,Egg!C27/Egg!C7) | L25: =Egg!C28
A26: Slaktekylling | B26: N | C26: kyllingar | D26: =Slaktekylling!C7 | E26: =Slaktekylling!C29 | F26: =Slaktekylling!C30 | G26: =Slaktekylling!C31 | H26: =Slaktekylling!C16 | I26: =Slaktekylling!C32 | J26: =IF(Slaktekylling!C7=0,0,Slaktekylling!C31/Slaktekylling!C7) | K26: =IF(Slaktekylling!C7=0,0,Slaktekylling!C32/Slaktekylling!C7) | L26: =Slaktekylling!C33
A27: Sum produksjonar med J | E27: =SUMIF($B$7:$B$26,"J",E7:E26) | F27: =SUMIF($B$7:$B$26,"J",F7:F26) | G27: =SUMIF($B$7:$B$26,"J",G7:G26) | H27: =SUMIF($B$7:$B$26,"J",H7:H26) | I27: =SUMIF($B$7:$B$26,"J",I7:I26) | L27: =SUMIF($B$7:$B$26,"J",L7:L26)
A29: Kontroll: Sum DB m/tilskot skal vere lik «Sum DB med tilskot» på Totaløkonomi:
A30: Avvik | I30: =I27-'Totaløkonomi'!C11

Sheet Totaløkonomi
A1: Totaløkonomi
A2: Summerer dekningsbidraget frå alle produksjonar som er med, trekkjer frå faste kostnader og avstemmer mot skattemessig resultat.
A3: Fargekodar: blå tal på gul botn = input (skal fyllast inn) · svart = formel · grøn = lenkje frå anna ark. Alle kronebeløp er positive (inntekt og kostnad).
A5: Post | B5: Kjelde / Tripletex-konto | C5: Verdi | D5: Eining | E5: Formel forklart (korleis outputen blir rekna) | F5: Excel-formel
A6: 1. UTREKNING – Dekningsbidrag frå produksjonane (berre produksjonar med i totalen)
A7: Sum produksjonsinntekter | B7: Utrekna | C7: =Korn!C24*IF(Oversikt!$B$7="J",1,0)+Silofor!C25*IF(Oversikt!$B$8="J",1,0)+'Høy'!C23*IF(Oversikt!$B$9="J",1,0)+Potet!C24*IF(Oversikt!$B$10="J",1,0)+Agurk!C25*IF(Oversikt!$B$11="J",1,0)+Tomat!C25*IF(Oversikt!$B$12="J",1,0)+'Frilandsgrønsak'!C24*IF(Oversikt!$B$13="J",1,0)+Gulrot!C24*IF(Oversikt!$B$14="J",1,0)+'Kålrot'!C24*IF(Oversikt!$B$15="J",1,0)+'Mjølk'!C50*IF(Oversikt!$B$16="J",1,0)+Oksar!C47*IF(Oversikt!$B$17="J",1,0)+Mellomkalv!C47*IF(Oversikt!$B$18="J",1,0)+Ammekyr!C52*IF(Oversikt!$B$19="J",1,0)+'Smågris'!C32*IF(Oversikt!$B$20="J",1,0)+Purkering!C33*IF(Oversikt!$B$21="J",1,0)+Slaktegris!C29*IF(Oversikt!$B$22="J",1,0)+Sau!C58*IF(Oversikt!$B$23="J",1,0)+Geit!C46*IF(Oversikt!$B$24="J",1,0)+Egg!C24*IF(Oversikt!$B$25="J",1,0)+Slaktekylling!C29*IF(Oversikt!$B$26="J",1,0) | D7: kr | E7: Sum produksjonsinntekter = Produksjonsinntekter i alt [Korn!C24] × Med i totalen Korn [Oversikt!B7 → 1/0] + Produksjonsinntekter i alt [Silofor!C25] × Med i totalen Silofor [Oversikt!B8 → 1/0] + Produksjonsinntekter i alt [Høy!C23] × Med i totalen Høy [Oversikt!B9 → 1/0] + Produksjonsinntekter i alt [Potet!C24] × Med i totalen Potet [Oversikt!B10 → 1/0] + Produksjonsinntekter i alt [Agurk!C25] × Med i totalen Agurk [Oversikt!B11 → 1/0] + Produksjonsinntekter i alt [Tomat!C25] × Med i totalen Tomat [Oversikt!B12 → 1/0] + Produksjonsinntekter i alt [Frilandsgrønsak!C24] × Med i totalen Frilandsgrønsak [Oversikt!B13 → 1/0] + Produksjonsinntekter i alt [Gulrot!C24] × Med i totalen Gulrot [Oversikt!B14 → 1/0] + Produksjonsinntekter i alt [Kålrot!C24] × Med i totalen Kålrot [Oversikt!B15 → 1/0] + Produksjonsinntekter i alt [Mjølk!C50] × Med i totalen Mjølk [Oversikt!B16 → 1/0] + Produksjonsinntekter i alt [Oksar!C47] × Med i totalen Oksar [Oversikt!B17 → 1/0] + Produksjonsinntekter i alt [Mellomkalv!C47] × Med i totalen Mellomkalv [Oversikt!B18 → 1/0] + Produksjonsinntekter i alt [Ammekyr!C52] × Med i totalen Ammekyr [Oversikt!B19 → 1/0] + Produksjonsinntekter i alt [Smågris!C32] × Med i totalen Smågris [Oversikt!B20 → 1/0] + Produksjonsinntekter i alt [Purkering!C33] × Med i totalen Purkering [Oversikt!B21 → 1/0] + Produksjonsinntekter i alt [Slaktegris!C29] × Med i totalen Slaktegris [Oversikt!B22 → 1/0] + Produksjonsinntekter i alt [Sau!C58] × Med i totalen Sau [Oversikt!B23 → 1/0] + Produksjonsinntekter i alt [Geit!C46] × Med i totalen Geit [Oversikt!B24 → 1/0] + Produksjonsinntekter i alt [Egg!C24] × Med i totalen Egg [Oversikt!B25 → 1/0] + Produksjonsinntekter i alt [Slaktekylling!C29] × Med i totalen Slaktekylling [Oversikt!B26 → 1/0] | F7: =Korn!C24*IF(Oversikt!$B$7="J",1,0)+Silofor!C25*IF(Oversikt!$B$8="J",1,0)+'Høy'!C23*IF(Oversikt!$B$9="J",1,0)+Potet!C24*IF(Oversikt!$B$10="J",1,0)+Agurk!C25*IF(Oversikt!$B$11="J",1,0)+Tomat!C25*IF(Oversikt!$B$12="J",1,0)+'Frilandsgrønsak'!C24*IF(Oversikt!$B$13="J",1,0)+Gulrot!C24*IF(Oversikt!$B$14="J",1,0)+'Kålrot'!C24*IF(Oversikt!$B$15="J",1,0)+'Mjølk'!C50*IF(Oversikt!$B$16="J",1,0)+Oksar!C47*IF(Oversikt!$B$17="J",1,0)+Mellomkalv!C47*IF(Oversikt!$B$18="J",1,0)+Ammekyr!C52*IF(Oversikt!$B$19="J",1,0)+'Smågris'!C32*IF(Oversikt!$B$20="J",1,0)+Purkering!C33*IF(Oversikt!$B$21="J",1,0)+Slaktegris!C29*IF(Oversikt!$B$22="J",1,0)+Sau!C58*IF(Oversikt!$B$23="J",1,0)+Geit!C46*IF(Oversikt!$B$24="J",1,0)+Egg!C24*IF(Oversikt!$B$25="J",1,0)+Slaktekylling!C29*IF(Oversikt!$B$26="J",1,0)
A8: Sum variable kostnader | B8: Utrekna | C8: =Korn!C25*IF(Oversikt!$B$7="J",1,0)+Silofor!C26*IF(Oversikt!$B$8="J",1,0)+'Høy'!C24*IF(Oversikt!$B$9="J",1,0)+Potet!C25*IF(Oversikt!$B$10="J",1,0)+Agurk!C26*IF(Oversikt!$B$11="J",1,0)+Tomat!C26*IF(Oversikt!$B$12="J",1,0)+'Frilandsgrønsak'!C25*IF(Oversikt!$B$13="J",1,0)+Gulrot!C25*IF(Oversikt!$B$14="J",1,0)+'Kålrot'!C25*IF(Oversikt!$B$15="J",1,0)+'Mjølk'!C55*IF(Oversikt!$B$16="J",1,0)+Oksar!C52*IF(Oversikt!$B$17="J",1,0)+Mellomkalv!C52*IF(Oversikt!$B$18="J",1,0)+Ammekyr!C57*IF(Oversikt!$B$19="J",1,0)+'Smågris'!C33*IF(Oversikt!$B$20="J",1,0)+Purkering!C34*IF(Oversikt!$B$21="J",1,0)+Slaktegris!C30*IF(Oversikt!$B$22="J",1,0)+Sau!C63*IF(Oversikt!$B$23="J",1,0)+Geit!C51*IF(Oversikt!$B$24="J",1,0)+Egg!C25*IF(Oversikt!$B$25="J",1,0)+Slaktekylling!C30*IF(Oversikt!$B$26="J",1,0) | D8: kr | E8: Sum variable kostnader = Variable kostnader i alt [Korn!C25] × Med i totalen Korn [Oversikt!B7 → 1/0] + Variable kostnader i alt [Silofor!C26] × Med i totalen Silofor [Oversikt!B8 → 1/0] + Variable kostnader i alt [Høy!C24] × Med i totalen Høy [Oversikt!B9 → 1/0] + Variable kostnader i alt [Potet!C25] × Med i totalen Potet [Oversikt!B10 → 1/0] + Variable kostnader i alt [Agurk!C26] × Med i totalen Agurk [Oversikt!B11 → 1/0] + Variable kostnader i alt [Tomat!C26] × Med i totalen Tomat [Oversikt!B12 → 1/0] + Variable kostnader i alt [Frilandsgrønsak!C25] × Med i totalen Frilandsgrønsak [Oversikt!B13 → 1/0] + Variable kostnader i alt [Gulrot!C25] × Med i totalen Gulrot [Oversikt!B14 → 1/0] + Variable kostnader i alt [Kålrot!C25] × Med i totalen Kålrot [Oversikt!B15 → 1/0] + Variable kostnader i alt [Mjølk!C55] × Med i totalen Mjølk [Oversikt!B16 → 1/0] + Variable kostnader i alt [Oksar!C52] × Med i totalen Oksar [Oversikt!B17 → 1/0] + Variable kostnader i alt [Mellomkalv!C52] × Med i totalen Mellomkalv [Oversikt!B18 → 1/0] + Variable kostnader i alt [Ammekyr!C57] × Med i totalen Ammekyr [Oversikt!B19 → 1/0] + Variable kostnader i alt [Smågris!C33] × Med i totalen Smågris [Oversikt!B20 → 1/0] + Variable kostnader i alt [Purkering!C34] × Med i totalen Purkering [Oversikt!B21 → 1/0] + Variable kostnader i alt [Slaktegris!C30] × Med i totalen Slaktegris [Oversikt!B22 → 1/0] + Variable kostnader i alt [Sau!C63] × Med i totalen Sau [Oversikt!B23 → 1/0] + Variable kostnader i alt [Geit!C51] × Med i totalen Geit [Oversikt!B24 → 1/0] + Variable kostnader i alt [Egg!C25] × Med i totalen Egg [Oversikt!B25 → 1/0] + Variable kostnader i alt [Slaktekylling!C30] × Med i totalen Slaktekylling [Oversikt!B26 → 1/0] | F8: =Korn!C25*IF(Oversikt!$B$7="J",1,0)+Silofor!C26*IF(Oversikt!$B$8="J",1,0)+'Høy'!C24*IF(Oversikt!$B$9="J",1,0)+Potet!C25*IF(Oversikt!$B$10="J",1,0)+Agurk!C26*IF(Oversikt!$B$11="J",1,0)+Tomat!C26*IF(Oversikt!$B$12="J",1,0)+'Frilandsgrønsak'!C25*IF(Oversikt!$B$13="J",1,0)+Gulrot!C25*IF(Oversikt!$B$14="J",1,0)+'Kålrot'!C25*IF(Oversikt!$B$15="J",1,0)+'Mjølk'!C55*IF(Oversikt!$B$16="J",1,0)+Oksar!C52*IF(Oversikt!$B$17="J",1,0)+Mellomkalv!C52*IF(Oversikt!$B$18="J",1,0)+Ammekyr!C57*IF(Oversikt!$B$19="J",1,0)+'Smågris'!C33*IF(Oversikt!$B$20="J",1,0)+Purkering!C34*IF(Oversikt!$B$21="J",1,0)+Slaktegris!C30*IF(Oversikt!$B$22="J",1,0)+Sau!C63*IF(Oversikt!$B$23="J",1,0)+Geit!C51*IF(Oversikt!$B$24="J",1,0)+Egg!C25*IF(Oversikt!$B$25="J",1,0)+Slaktekylling!C30*IF(Oversikt!$B$26="J",1,0)
A9: Sum DB utan tilskot | B9: Utrekna | C9: =Korn!C26*IF(Oversikt!$B$7="J",1,0)+Silofor!C27*IF(Oversikt!$B$8="J",1,0)+'Høy'!C25*IF(Oversikt!$B$9="J",1,0)+Potet!C26*IF(Oversikt!$B$10="J",1,0)+Agurk!C27*IF(Oversikt!$B$11="J",1,0)+Tomat!C27*IF(Oversikt!$B$12="J",1,0)+'Frilandsgrønsak'!C26*IF(Oversikt!$B$13="J",1,0)+Gulrot!C26*IF(Oversikt!$B$14="J",1,0)+'Kålrot'!C26*IF(Oversikt!$B$15="J",1,0)+'Mjølk'!C56*IF(Oversikt!$B$16="J",1,0)+Oksar!C53*IF(Oversikt!$B$17="J",1,0)+Mellomkalv!C53*IF(Oversikt!$B$18="J",1,0)+Ammekyr!C58*IF(Oversikt!$B$19="J",1,0)+'Smågris'!C34*IF(Oversikt!$B$20="J",1,0)+Purkering!C35*IF(Oversikt!$B$21="J",1,0)+Slaktegris!C31*IF(Oversikt!$B$22="J",1,0)+Sau!C64*IF(Oversikt!$B$23="J",1,0)+Geit!C52*IF(Oversikt!$B$24="J",1,0)+Egg!C26*IF(Oversikt!$B$25="J",1,0)+Slaktekylling!C31*IF(Oversikt!$B$26="J",1,0) | D9: kr | E9: Sum DB utan tilskot = Dekningsbidrag (DB) utan tilskot [Korn!C26] × Med i totalen Korn [Oversikt!B7 → 1/0] + Dekningsbidrag (DB) utan tilskot [Silofor!C27] × Med i totalen Silofor [Oversikt!B8 → 1/0] + Dekningsbidrag (DB) utan tilskot [Høy!C25] × Med i totalen Høy [Oversikt!B9 → 1/0] + Dekningsbidrag (DB) utan tilskot [Potet!C26] × Med i totalen Potet [Oversikt!B10 → 1/0] + Dekningsbidrag (DB) utan tilskot [Agurk!C27] × Med i totalen Agurk [Oversikt!B11 → 1/0] + Dekningsbidrag (DB) utan tilskot [Tomat!C27] × Med i totalen Tomat [Oversikt!B12 → 1/0] + Dekningsbidrag (DB) utan tilskot [Frilandsgrønsak!C26] × Med i totalen Frilandsgrønsak [Oversikt!B13 → 1/0] + Dekningsbidrag (DB) utan tilskot [Gulrot!C26] × Med i totalen Gulrot [Oversikt!B14 → 1/0] + Dekningsbidrag (DB) utan tilskot [Kålrot!C26] × Med i totalen Kålrot [Oversikt!B15 → 1/0] + Dekningsbidrag (DB) utan tilskot [Mjølk!C56] × Med i totalen Mjølk [Oversikt!B16 → 1/0] + Dekningsbidrag (DB) utan tilskot [Oksar!C53] × Med i totalen Oksar [Oversikt!B17 → 1/0] + Dekningsbidrag (DB) utan tilskot [Mellomkalv!C53] × Med i totalen Mellomkalv [Oversikt!B18 → 1/0] + Dekningsbidrag (DB) utan tilskot [Ammekyr!C58] × Med i totalen Ammekyr [Oversikt!B19 → 1/0] + Dekningsbidrag (DB) utan tilskot [Smågris!C34] × Med i totalen Smågris [Oversikt!B20 → 1/0] + Dekningsbidrag (DB) utan tilskot [Purkering!C35] × Med i totalen Purkering [Oversikt!B21 → 1/0] + Dekningsbidrag (DB) utan tilskot [Slaktegris!C31] × Med i totalen Slaktegris [Oversikt!B22 → 1/0] + Dekningsbidrag (DB) utan tilskot [Sau!C64] × Med i totalen Sau [Oversikt!B23 → 1/0] + Dekningsbidrag (DB) utan tilskot [Geit!C52] × Med i totalen Geit [Oversikt!B24 → 1/0] + Dekningsbidrag (DB) utan tilskot [Egg!C26] × Med i totalen Egg [Oversikt!B25 → 1/0] + Dekningsbidrag (DB) utan tilskot [Slaktekylling!C31] × Med i totalen Slaktekylling [Oversikt!B26 → 1/0] | F9: =Korn!C26*IF(Oversikt!$B$7="J",1,0)+Silofor!C27*IF(Oversikt!$B$8="J",1,0)+'Høy'!C25*IF(Oversikt!$B$9="J",1,0)+Potet!C26*IF(Oversikt!$B$10="J",1,0)+Agurk!C27*IF(Oversikt!$B$11="J",1,0)+Tomat!C27*IF(Oversikt!$B$12="J",1,0)+'Frilandsgrønsak'!C26*IF(Oversikt!$B$13="J",1,0)+Gulrot!C26*IF(Oversikt!$B$14="J",1,0)+'Kålrot'!C26*IF(Oversikt!$B$15="J",1,0)+'Mjølk'!C56*IF(Oversikt!$B$16="J",1,0)+Oksar!C53*IF(Oversikt!$B$17="J",1,0)+Mellomkalv!C53*IF(Oversikt!$B$18="J",1,0)+Ammekyr!C58*IF(Oversikt!$B$19="J",1,0)+'Smågris'!C34*IF(Oversikt!$B$20="J",1,0)+Purkering!C35*IF(Oversikt!$B$21="J",1,0)+Slaktegris!C31*IF(Oversikt!$B$22="J",1,0)+Sau!C64*IF(Oversikt!$B$23="J",1,0)+Geit!C52*IF(Oversikt!$B$24="J",1,0)+Egg!C26*IF(Oversikt!$B$25="J",1,0)+Slaktekylling!C31*IF(Oversikt!$B$26="J",1,0)
A10: Sum tilskot fordelt på produksjonane | B10: Utrekna | C10: =Korn!C11*IF(Oversikt!$B$7="J",1,0)+Silofor!C13*IF(Oversikt!$B$8="J",1,0)+'Høy'!C11*IF(Oversikt!$B$9="J",1,0)+Potet!C11*IF(Oversikt!$B$10="J",1,0)+Agurk!C11*IF(Oversikt!$B$11="J",1,0)+Tomat!C11*IF(Oversikt!$B$12="J",1,0)+'Frilandsgrønsak'!C11*IF(Oversikt!$B$13="J",1,0)+Gulrot!C11*IF(Oversikt!$B$14="J",1,0)+'Kålrot'!C11*IF(Oversikt!$B$15="J",1,0)+'Mjølk'!C21*IF(Oversikt!$B$16="J",1,0)+Oksar!C20*IF(Oversikt!$B$17="J",1,0)+Mellomkalv!C20*IF(Oversikt!$B$18="J",1,0)+Ammekyr!C25*IF(Oversikt!$B$19="J",1,0)+'Smågris'!C17*IF(Oversikt!$B$20="J",1,0)+Purkering!C17*IF(Oversikt!$B$21="J",1,0)+Slaktegris!C16*IF(Oversikt!$B$22="J",1,0)+Sau!C29*IF(Oversikt!$B$23="J",1,0)+Geit!C18*IF(Oversikt!$B$24="J",1,0)+Egg!C11*IF(Oversikt!$B$25="J",1,0)+Slaktekylling!C16*IF(Oversikt!$B$26="J",1,0) | D10: kr | E10: Sum tilskot fordelt på produksjonane = Produksjonstilskot fordelt på produksjonen [Korn!C11] × Med i totalen Korn [Oversikt!B7 → 1/0] + Produksjonstilskot fordelt på produksjonen [Silofor!C13] × Med i totalen Silofor [Oversikt!B8 → 1/0] + Produksjonstilskot fordelt på produksjonen [Høy!C11] × Med i totalen Høy [Oversikt!B9 → 1/0] + Produksjonstilskot fordelt på produksjonen [Potet!C11] × Med i totalen Potet [Oversikt!B10 → 1/0] + Produksjonstilskot fordelt på produksjonen [Agurk!C11] × Med i totalen Agurk [Oversikt!B11 → 1/0] + Produksjonstilskot fordelt på produksjonen [Tomat!C11] × Med i totalen Tomat [Oversikt!B12 → 1/0] + Produksjonstilskot fordelt på produksjonen [Frilandsgrønsak!C11] × Med i totalen Frilandsgrønsak [Oversikt!B13 → 1/0] + Produksjonstilskot fordelt på produksjonen [Gulrot!C11] × Med i totalen Gulrot [Oversikt!B14 → 1/0] + Produksjonstilskot fordelt på produksjonen [Kålrot!C11] × Med i totalen Kålrot [Oversikt!B15 → 1/0] + Produksjonstilskot fordelt på produksjonen [Mjølk!C21] × Med i totalen Mjølk [Oversikt!B16 → 1/0] + Produksjonstilskot fordelt på produksjonen [Oksar!C20] × Med i totalen Oksar [Oversikt!B17 → 1/0] + Produksjonstilskot fordelt på produksjonen [Mellomkalv!C20] × Med i totalen Mellomkalv [Oversikt!B18 → 1/0] + Produksjonstilskot fordelt på produksjonen [Ammekyr!C25] × Med i totalen Ammekyr [Oversikt!B19 → 1/0] + Produksjonstilskot fordelt på produksjonen [Smågris!C17] × Med i totalen Smågris [Oversikt!B20 → 1/0] + Produksjonstilskot fordelt på produksjonen [Purkering!C17] × Med i totalen Purkering [Oversikt!B21 → 1/0] + Produksjonstilskot fordelt på produksjonen [Slaktegris!C16] × Med i totalen Slaktegris [Oversikt!B22 → 1/0] + Produksjonstilskot fordelt på produksjonen [Sau!C29] × Med i totalen Sau [Oversikt!B23 → 1/0] + Produksjonstilskot fordelt på produksjonen [Geit!C18] × Med i totalen Geit [Oversikt!B24 → 1/0] + Produksjonstilskot fordelt på produksjonen [Egg!C11] × Med i totalen Egg [Oversikt!B25 → 1/0] + Produksjonstilskot fordelt på produksjonen [Slaktekylling!C16] × Med i totalen Slaktekylling [Oversikt!B26 → 1/0] | F10: =Korn!C11*IF(Oversikt!$B$7="J",1,0)+Silofor!C13*IF(Oversikt!$B$8="J",1,0)+'Høy'!C11*IF(Oversikt!$B$9="J",1,0)+Potet!C11*IF(Oversikt!$B$10="J",1,0)+Agurk!C11*IF(Oversikt!$B$11="J",1,0)+Tomat!C11*IF(Oversikt!$B$12="J",1,0)+'Frilandsgrønsak'!C11*IF(Oversikt!$B$13="J",1,0)+Gulrot!C11*IF(Oversikt!$B$14="J",1,0)+'Kålrot'!C11*IF(Oversikt!$B$15="J",1,0)+'Mjølk'!C21*IF(Oversikt!$B$16="J",1,0)+Oksar!C20*IF(Oversikt!$B$17="J",1,0)+Mellomkalv!C20*IF(Oversikt!$B$18="J",1,0)+Ammekyr!C25*IF(Oversikt!$B$19="J",1,0)+'Smågris'!C17*IF(Oversikt!$B$20="J",1,0)+Purkering!C17*IF(Oversikt!$B$21="J",1,0)+Slaktegris!C16*IF(Oversikt!$B$22="J",1,0)+Sau!C29*IF(Oversikt!$B$23="J",1,0)+Geit!C18*IF(Oversikt!$B$24="J",1,0)+Egg!C11*IF(Oversikt!$B$25="J",1,0)+Slaktekylling!C16*IF(Oversikt!$B$26="J",1,0)
A11: Sum DB med tilskot | B11: Utrekna | C11: =C9+C10 | D11: kr | E11: Sum DB med tilskot = Sum DB utan tilskot [C9] + Sum tilskot fordelt på produksjonane [C10] | F11: =C9+C10
A12: 2. INPUT – Inntekter og kostnader som ikkje er fordelt på produksjon
A13: Andre driftsinntekter, netto (ikkje fordelt på produksjon) | B13: 3090-3092, 3600-3999 o.l. | C13: 228384.97 | D13: kr | E13: Input. Hentast frå: 3090-3092, 3600-3999 o.l.. Eksempel: DB totalt minus DB i produksjonane i vedlagt analyse (Prod.øk «Andre inntekter»).
A14: Tilskot som ikkje er fordelt på produksjon | B14: 34xx | C14: 0 | D14: kr | E14: Input. Hentast frå: 34xx.
A15: Variable kostnader som ikkje er fordelt | B15: 4xxx | C15: 0 | D15: kr | E15: Input. Hentast frå: 4xxx.
A16: 3. UTREKNING – Driftsoverskot jordbruk (driftsmessig)
A17: Sum faste kostnader | B17: Lenkje frå anna ark | C17: ='Faste kostnader'!C102 | D17: kr | E17: Sum faste kostnader = Sum faste kostnader jordbruk [Faste kostnader!C102] | F17: ='Faste kostnader'!C102
A18: Driftsoverskot jordbruk, driftsmessig | B18: Utrekna | C18: =C11+C13+C14-C15-C17 | D18: kr | E18: Driftsoverskot jordbruk, driftsmessig = Sum DB med tilskot [C11] + Andre driftsinntekter, netto (ikkje fordelt på produksjon) [C13] + Tilskot som ikkje er fordelt på produksjon [C14] − Variable kostnader som ikkje er fordelt [C15] − Sum faste kostnader [C17] | F18: =C11+C13+C14-C15-C17
A19: 4. INPUT – Skattemessige tal frå rekneskapen (for avstemming)
A20: Skattemessige avskrivingar | B20: 60xx i saldobalansen (før korrigering) | C20: 8882.16 | D20: kr | E20: Input. Hentast frå: 60xx i saldobalansen (før korrigering).
A21: Driftsmessige avskrivingar | B21: 60xx i saldobalansen (etter korrigering) | C21: 246072.11 | D21: kr | E21: Input. Hentast frå: 60xx i saldobalansen (etter korrigering).
A22: Beholdningsendring buskap/varelager, skattemessig (+ = auke) | B22: 4090-4099, 4190-4199, 4290-4299, 4690-4699 (før korrigering) | C22: -58135 | D22: kr | E22: Input. Hentast frå: 4090-4099, 4190-4199, 4290-4299, 4690-4699 (før korrigering).
A23: Beholdningsendring buskap/varelager, driftsmessig (+ = auke) | B23: Etter korrigering til driftsmessige verdiar | C23: 3740 | D23: kr | E23: Input. Hentast frå: Etter korrigering til driftsmessige verdiar.
A24: Driftsoverskot jordbruk i rekneskapen (skatt) | B24: Næringsoppgåve / resultatrekneskap | C24: 403480.85 | D24: kr | E24: Input. Hentast frå: Næringsoppgåve / resultatrekneskap.
A25: 5. UTREKNING – Frå skattemessig til driftsmessig resultat
A26: Korrigering avskrivingar (skatt – drift) | B26: Utrekna | C26: =C20-C21 | D26: kr | E26: Korrigering avskrivingar (skatt – drift) = Skattemessige avskrivingar [C20] − Driftsmessige avskrivingar [C21] | F26: =C20-C21
A27: Korrigering beholdningsendring (drift – skatt) | B27: Utrekna | C27: =C23-C22 | D27: kr | E27: Korrigering beholdningsendring (drift – skatt) = Beholdningsendring buskap/varelager, driftsmessig (+ = auke) [C23] − Beholdningsendring buskap/varelager, skattemessig (+ = auke) [C22] | F27: =C23-C22
A28: Driftsoverskot skattemessig, berekna | B28: Utrekna | C28: =C18-C26-C27 | D28: kr | E28: Driftsoverskot skattemessig, berekna = Driftsoverskot jordbruk, driftsmessig [C18] − Korrigering avskrivingar (skatt – drift) [C26] − Korrigering beholdningsendring (drift – skatt) [C27] | F28: =C18-C26-C27
A29: Avvik mot rekneskapen (bør vere 0) | B29: Utrekna | C29: =C24-C28 | D29: kr | E29: Avvik mot rekneskapen (bør vere 0) = Driftsoverskot jordbruk i rekneskapen (skatt) [C24] − Driftsoverskot skattemessig, berekna [C28] (Avvik kjem av postar som ikkje er lagt inn i analysen. Eksempelanalysen har same avvik (−329,66)) | F29: =C24-C28
A30: 6. INPUT/UTREKNING – Nettoinntekt
A31: Driftsoverskot andre næringar (skog, leigekøyring o.l.) | B31: Avdeling 30/70 o.l. | C31: 117592.22 | D31: kr | E31: Input. Hentast frå: Avdeling 30/70 o.l..
A32: Renteinntekter | B32: 80xx | C32: 117 | D32: kr | E32: Input. Hentast frå: 80xx.
A33: Renteutgifter | B33: 8100-8179 | C33: 190284.05 | D33: kr | E33: Input. Hentast frå: 8100-8179.
A34: Nettoinntekt næring (driftsmessig) | B34: Utrekna | C34: =C18+C31+C32-C33 | D34: kr | E34: Nettoinntekt næring (driftsmessig) = Driftsoverskot jordbruk, driftsmessig [C18] + Driftsoverskot andre næringar (skog, leigekøyring o.l.) [C31] + Renteinntekter [C32] − Renteutgifter [C33] | F34: =C18+C31+C32-C33
A35: 7. OUTPUT – Nøkkeltal totaløkonomi
A36: DB m/tilskot i % av produksjonsinntekter og tilskot | B36: Utrekna | C36: =IF((C7+C10)=0,0,(C11)/(C7+C10)) | D36: % | E36: DB m/tilskot i % av produksjonsinntekter og tilskot = Sum DB med tilskot [C11] ÷ (Sum produksjonsinntekter [C7] + Sum tilskot fordelt på produksjonane [C10]) | F36: =IF((C7+C10)=0,0,(C11)/(C7+C10))
A37: Tilskot i % av DB m/tilskot | B37: Utrekna | C37: =IF((C11)=0,0,(C10)/(C11)) | D37: % | E37: Tilskot i % av DB m/tilskot = Sum tilskot fordelt på produksjonane [C10] ÷ Sum DB med tilskot [C11] | F37: =IF((C11)=0,0,(C10)/(C11))
A38: Faste kostnader i % av DB m/tilskot | B38: Utrekna | C38: =IF((C11)=0,0,(C17)/(C11)) | D38: % | E38: Faste kostnader i % av DB m/tilskot = Sum faste kostnader [C17] ÷ Sum DB med tilskot [C11] | F38: =IF((C11)=0,0,(C17)/(C11))
A39: Renteutgifter i % av driftsoverskot | B39: Utrekna | C39: =IF((C18)=0,0,(C33)/(C18)) | D39: % | E39: Renteutgifter i % av driftsoverskot = Renteutgifter [C33] ÷ Driftsoverskot jordbruk, driftsmessig [C18] | F39: =IF((C18)=0,0,(C33)/(C18))

Sheet Faste kostnader
A1: Faste kostnader jordbruk
A2: Maskin-, bygnings- og andre faste kostnader. Maskinkostnader og innandørsmekanisering blir fordelt på produksjonane.
A3: Fargekodar: blå tal på gul botn = input (skal fyllast inn) · svart = formel · grøn = lenkje frå anna ark. Alle kronebeløp er positive (inntekt og kostnad).
A5: Post | B5: Kjelde / Tripletex-konto | C5: Verdi | D5: Eining | E5: Formel forklart (korleis outputen blir rekna) | F5: Excel-formel
A6: 1. INPUT – Maskinkostnader (driftsmessige tal)
A7: Vedlikehald maskiner og reiskap | B7: 6620-6629 | C7: 27820.2 | D7: kr | E7: Input. Hentast frå: 6620-6629.
A8: Drivstoff | B8: 6250-6259 | C8: 18004.8 | D8: kr | E8: Input. Hentast frå: 6250-6259.
A9: Maskinleige / leigekøyring / bruk av eigen traktor | B9: 4550-4559, 6400-6409, 6450-6452 | C9: 84250.8 | D9: kr | E9: Input. Hentast frå: 4550-4559, 6400-6409, 6450-6452.
A10: Leasing maskiner | B10: 6470, 6473 | C10: 0 | D10: kr | E10: Input. Hentast frå: 6470, 6473.
A11: Avskrivingar maskiner og reiskap (driftsmessige) | B11: 6010 | C11: 98462.99 | D11: kr | E11: Input. Hentast frå: 6010.
A12: Andre maskinkostnader (forsikring, småreiskap) | B12: 6500-6529, 7503 | C12: 14251 | D12: kr | E12: Input. Hentast frå: 6500-6529, 7503.
A13: Sum maskinkostnader | B13: Utrekna | C13: =C7+C8+C9+C10+C11+C12 | D13: kr | E13: Sum maskinkostnader = Vedlikehald maskiner og reiskap [C7] + Drivstoff [C8] + Maskinleige / leigekøyring / bruk av eigen traktor [C9] + Leasing maskiner [C10] + Avskrivingar maskiner og reiskap (driftsmessige) [C11] + Andre maskinkostnader (forsikring, småreiskap) [C12] | F13: =C7+C8+C9+C10+C11+C12
A14: 2. INPUT – Fordeling av maskinkostnader på produksjonane (%)
A15: Del maskinkostnad – Korn | B15: Skjønn / timeforbruk | C15: 0 | D15: % | E15: Input. Hentast frå: Skjønn / timeforbruk.
A16: Del maskinkostnad – Silofor | B16: Skjønn / timeforbruk | C16: 0.32183936 | D16: % | E16: Input. Hentast frå: Skjønn / timeforbruk. Eksempel: fordelt som i vedlagt analyse
A17: Del maskinkostnad – Høy | B17: Skjønn / timeforbruk | C17: 0 | D17: % | E17: Input. Hentast frå: Skjønn / timeforbruk.
A18: Del maskinkostnad – Potet | B18: Skjønn / timeforbruk | C18: 0 | D18: % | E18: Input. Hentast frå: Skjønn / timeforbruk.
A19: Del maskinkostnad – Agurk | B19: Skjønn / timeforbruk | C19: 0 | D19: % | E19: Input. Hentast frå: Skjønn / timeforbruk.
A20: Del maskinkostnad – Tomat | B20: Skjønn / timeforbruk | C20: 0 | D20: % | E20: Input. Hentast frå: Skjønn / timeforbruk.
A21: Del maskinkostnad – Frilandsgrønsak | B21: Skjønn / timeforbruk | C21: 0 | D21: % | E21: Input. Hentast frå: Skjønn / timeforbruk.
A22: Del maskinkostnad – Gulrot | B22: Skjønn / timeforbruk | C22: 0 | D22: % | E22: Input. Hentast frå: Skjønn / timeforbruk.
A23: Del maskinkostnad – Kålrot | B23: Skjønn / timeforbruk | C23: 0 | D23: % | E23: Input. Hentast frå: Skjønn / timeforbruk.
A24: Del maskinkostnad – Mjølk | B24: Skjønn / timeforbruk | C24: 0 | D24: % | E24: Input. Hentast frå: Skjønn / timeforbruk.
A25: Del maskinkostnad – Oksar | B25: Skjønn / timeforbruk | C25: 0 | D25: % | E25: Input. Hentast frå: Skjønn / timeforbruk.
A26: Del maskinkostnad – Mellomkalv | B26: Skjønn / timeforbruk | C26: 0 | D26: % | E26: Input. Hentast frå: Skjønn / timeforbruk.
... A34: Del maskinkostnad – Slaktekylling | B34: Skjønn / timeforbruk | C34: 0 | D34: % | E34: Input. Hentast frå: Skjønn / timeforbruk.
A35: Del maskinkostnad – anna bruk (rest) | B35: Utrekna | C35: =1-(C15+C16+C17+C18+C19+C20+C21+C22+C23+C24+C25+C26+C27+C28+C29+C30+C31+C32+C33+C34) | D35: % | E35: Del maskinkostnad – anna bruk (rest) = 1 − (Del maskinkostnad – Korn [C15] + Del maskinkostnad – Silofor [C16] + Del maskinkostnad – Høy [C17] + Del maskinkostnad – Potet [C18] + Del maskinkostnad – Agurk [C19] + Del maskinkostnad – Tomat [C20] + Del maskinkostnad – Frilandsgrønsak [C21] + Del maskinkostnad – Gulrot [C22] + Del maskinkostnad – Kålrot [C23] + Del maskinkostnad – Mjølk [C24] + Del maskinkostnad – Oksar [C25] + Del maskinkostnad – Mellomkalv [C26] + Del maskinkostnad – Ammekyr [C27] + Del maskinkostnad – Smågris [C28] + Del maskinkostnad – Purkering [C29] + Del maskinkostnad – Slaktegris [C30] + Del maskinkostnad – Sau [C31] + Del maskinkostnad – Geit [C32] + Del maskinkostnad – Egg [C33] + Del maskinkostnad – Slaktekylling [C34]) | F35: =1-(C15+C16+C17+C18+C19+C20+C21+C22+C23+C24+C25+C26+C27+C28+C29+C30+C31+C32+C33+C34)
A36: 3. UTREKNING – Maskinkostnader fordelt (kr)
A37: Maskinkostnader – Korn | B37: Utrekna | C37: =C13*C15 | D37: kr | E37: Maskinkostnader – Korn = Sum maskinkostnader [C13] × Del maskinkostnad – Korn [C15] | F37: =C13*C15
A38: Maskinkostnader – Silofor | B38: Utrekna | C38: =C13*C16 | D38: kr | E38: Maskinkostnader – Silofor = Sum maskinkostnader [C13] × Del maskinkostnad – Silofor [C16] | F38: =C13*C16
A39: Maskinkostnader – Høy | B39: Utrekna | C39: =C13*C17 | D39: kr | E39: Maskinkostnader – Høy = Sum maskinkostnader [C13] × Del maskinkostnad – Høy [C17] | F39: =C13*C17
A40: Maskinkostnader – Potet | B40: Utrekna | C40: =C13*C18 | D40: kr | E40: Maskinkostnader – Potet = Sum maskinkostnader [C13] × Del maskinkostnad – Potet [C18] | F40: =C13*C18
A41: Maskinkostnader – Agurk | B41: Utrekna | C41: =C13*C19 | D41: kr | E41: Maskinkostnader – Agurk = Sum maskinkostnader [C13] × Del maskinkostnad – Agurk [C19] | F41: =C13*C19
A42: Maskinkostnader – Tomat | B42: Utrekna | C42: =C13*C20 | D42: kr | E42: Maskinkostnader – Tomat = Sum maskinkostnader [C13] × Del maskinkostnad – Tomat [C20] | F42: =C13*C20
A43: Maskinkostnader – Frilandsgrønsak | B43: Utrekna | C43: =C13*C21 | D43: kr | E43: Maskinkostnader – Frilandsgrønsak = Sum maskinkostnader [C13] × Del maskinkostnad – Frilandsgrønsak [C21] | F43: =C13*C21
A44: Maskinkostnader – Gulrot | B44: Utrekna | C44: =C13*C22 | D44: kr | E44: Maskinkostnader – Gulrot = Sum maskinkostnader [C13] × Del maskinkostnad – Gulrot [C22] | F44: =C13*C22
A45: Maskinkostnader – Kålrot | B45: Utrekna | C45: =C13*C23 | D45: kr | E45: Maskinkostnader – Kålrot = Sum maskinkostnader [C13] × Del maskinkostnad – Kålrot [C23] | F45: =C13*C23
A46: Maskinkostnader – Mjølk | B46: Utrekna | C46: =C13*C24 | D46: kr | E46: Maskinkostnader – Mjølk = Sum maskinkostnader [C13] × Del maskinkostnad – Mjølk [C24] | F46: =C13*C24
A47: Maskinkostnader – Oksar | B47: Utrekna | C47: =C13*C25 | D47: kr | E47: Maskinkostnader – Oksar = Sum maskinkostnader [C13] × Del maskinkostnad – Oksar [C25] | F47: =C13*C25
A48: Maskinkostnader – Mellomkalv | B48: Utrekna | C48: =C13*C26 | D48: kr | E48: Maskinkostnader – Mellomkalv = Sum maskinkostnader [C13] × Del maskinkostnad – Mellomkalv [C26] | F48: =C13*C26
...

Sheet Grovfôr
A1: Grovfôr – areal, kueiningar og grovfôrkostnad
A2: Felles grovfôrgrunnlag for mjølk, oksar, mellomkalv, ammekyr, sau og geit.
A3: Fargekodar: blå tal på gul botn = input (skal fyllast inn) · svart = formel · grøn = lenkje frå anna ark. Alle kronebeløp er positive (inntekt og kostnad).
A5: Post | B5: Kjelde / Tripletex-konto | C5: Verdi | D5: Eining | E5: Formel forklart (korleis outputen blir rekna) | F5: Excel-formel
A6: 1. INPUT – Areal (dekar)
A7: Overflatedyrka jord til eng og beite | B7: Søknad om produksjonstilskot / kontoar 1071 mengd 2 | C7: 0 | D7: da | E7: Input. Hentast frå: Søknad om produksjonstilskot / kontoar 1071 mengd 2.
A8: Fulldyrka jord til eng og beite | B8: Søknad om produksjonstilskot / konto 1070 mengd 2 | C8: 129 | D8: da | E8: Input. Hentast frå: Søknad om produksjonstilskot / konto 1070 mengd 2.
A9: Innmarksbeite / kulturbeite | B9: Søknad om produksjonstilskot / konto 1072 mengd 2 | C9: 169 | D9: da | E9: Input. Hentast frå: Søknad om produksjonstilskot / konto 1072 mengd 2.
A10: Kulturbeite leigd ut | B10: Leigeavtalar | C10: 0 | D10: da | E10: Input. Hentast frå: Leigeavtalar.
A11: 2. INPUT – Dyr på utmarksbeite (tal dyr sleppt)
A12: Sau på utmarksbeite (1,05 FEm/dag, 95 dagar) | B12: Søknad om tilskot til dyr på beite | C12: 36 | D12: stk | E12: Input. Hentast frå: Søknad om tilskot til dyr på beite.
A13: Lam på utmarksbeite (1 FEm/dag, 90 dagar) | B13: Søknad om tilskot til dyr på beite | C13: 0 | D13: stk | E13: Input. Hentast frå: Søknad om tilskot til dyr på beite.
A14: Kyr på utmarksbeite (7,2 FEm/dag, 92 dagar) | B14: Søknad om tilskot til dyr på beite | C14: 16 | D14: stk | E14: Input. Hentast frå: Søknad om tilskot til dyr på beite.
A15: Ungdyr på utmarksbeite (4,8 FEm/dag, 92 dagar) | B15: Søknad om tilskot til dyr på beite | C15: 21 | D15: stk | E15: Input. Hentast frå: Søknad om tilskot til dyr på beite.
A16: 3. UTREKNING – Grovfôrareal
A17: Dekar til sal av silofôr og høy | B17: Utrekna | C17: =Silofor!C7*IF(Oversikt!$B$8="J",1,0)+'Høy'!C7*IF(Oversikt!$B$9="J",1,0) | D17: da | E17: Dekar til sal av silofôr og høy = Tal dekar [Silofor!C7] × Med i totalen Silofor [Oversikt!B8 → 1/0] + Tal dekar [Høy!C7] × Med i totalen Høy [Oversikt!B9 → 1/0] | F17: =Silofor!C7*IF(Oversikt!$B$8="J",1,0)+'Høy'!C7*IF(Oversikt!$B$9="J",1,0)
A18: Fulldyrka til eigen grovfôrbasert husdyrproduksjon | B18: Utrekna | C18: =C8-C17 | D18: da | E18: Fulldyrka til eigen grovfôrbasert husdyrproduksjon = Fulldyrka jord til eng og beite [C8] − Dekar til sal av silofôr og høy [C17] | F18: =C8-C17
A19: Kulturbeite til eige bruk | B19: Utrekna | C19: =C9-C10 | D19: da | E19: Kulturbeite til eige bruk = Innmarksbeite / kulturbeite [C9] − Kulturbeite leigd ut [C10] | F19: =C9-C10
A20: Dekar grovfôr – maskinkostnadsgrunnlag (overflate/2 + fulldyrka + kulturbeite×10 %) | B20: Utrekna | C20: =C7/2+C18+C19*0.1 | D20: da | E20: Dekar grovfôr – maskinkostnadsgrunnlag (overflate/2 + fulldyrka + kulturbeite×10 %) = Overflatedyrka jord til eng og beite [C7] / 2 + Fulldyrka til eigen grovfôrbasert husdyrproduksjon [C18] + Kulturbeite til eige bruk [C19] × 0,1 | F20: =C7/2+C18+C19*0.1
A21: Korrigert grovfôrareal (overflate/1,25 + fulldyrka + kulturbeite/2,5) | B21: Utrekna | C21: =C7/1.25+C18+C19/2.5 | D21: da | E21: Korrigert grovfôrareal (overflate/1,25 + fulldyrka + kulturbeite/2,5) = Overflatedyrka jord til eng og beite [C7] / 1,25 + Fulldyrka til eigen grovfôrbasert husdyrproduksjon [C18] + Kulturbeite til eige bruk [C19] / 2,5 | F21: =C7/1.25+C18+C19/2.5
A22: Fôreiningar (FEm) henta frå utmark | B22: Utrekna | C22: =C12*1.05*95+C13*1*90+C14*7.2*92+C15*4.8*92 | D22: FEm | E22: Fôreiningar (FEm) henta frå utmark = Sau på utmarksbeite (1,05 FEm/dag, 95 dagar) [C12] × 1,05 × 95 + Lam på utmarksbeite (1 FEm/dag, 90 dagar) [C13] × 1 × 90 + Kyr på utmarksbeite (7,2 FEm/dag, 92 dagar) [C14] × 7,2 × 92 + Ungdyr på utmarksbeite (4,8 FEm/dag, 92 dagar) [C15] × 4,8 × 92 | F22: =C12*1.05*95+C13*1*90+C14*7.2*92+C15*4.8*92
A23: Utmark omrekna til «fulldyrka» dekar (900 FEm/da) | B23: Utrekna | C23: =C22/900 | D23: da | E23: Utmark omrekna til «fulldyrka» dekar (900 FEm/da) = Fôreiningar (FEm) henta frå utmark [C22] / 900 | F23: =C22/900
A24: 4. UTREKNING – «Kueiningar» og eigen grovfôrkostnad pr produksjon (berre produksjonar med i totalen)
A25: Kueiningar – Mjølk | B25: Utrekna | C25: ='Mjølk'!C59*IF(Oversikt!$B$16="J",1,0) | D25: stk | E25: Kueiningar – Mjølk = «Kueiningar» [Mjølk!C59] × Med i totalen Mjølk [Oversikt!B16 → 1/0] | F25: ='Mjølk'!C59*IF(Oversikt!$B$16="J",1,0)
A26: Kueiningar – Oksar | B26: Utrekna | C26: =Oksar!C56*IF(Oversikt!$B$17="J",1,0) | D26: stk | E26: Kueiningar – Oksar = «Kueiningar» [Oksar!C56] × Med i totalen Oksar [Oversikt!B17 → 1/0] | F26: =Oksar!C56*IF(Oversikt!$B$17="J",1,0)
A27: Kueiningar – Mellomkalv | B27: Utrekna | C27: =Mellomkalv!C56*IF(Oversikt!$B$18="J",1,0) | D27: stk | E27: Kueiningar – Mellomkalv = «Kueiningar» [Mellomkalv!C56] × Med i totalen Mellomkalv [Oversikt!B18 → 1/0] | F27: =Mellomkalv!C56*IF(Oversikt!$B$18="J",1,0)
A28: Kueiningar – Ammekyr | B28: Utrekna | C28: =Ammekyr!C61*IF(Oversikt!$B$19="J",1,0) | D28: stk | E28: Kueiningar – Ammekyr = «Kueiningar» [Ammekyr!C61] × Med i totalen Ammekyr [Oversikt!B19 → 1/0] | F28: =Ammekyr!C61*IF(Oversikt!$B$19="J",1,0)
A29: Kueiningar – Sau | B29: Utrekna | C29: =Sau!C67*IF(Oversikt!$B$23="J",1,0) | D29: stk | E29: Kueiningar – Sau = «Kueiningar» [Sau!C67] × Med i totalen Sau [Oversikt!B23 → 1/0] | F29: =Sau!C67*IF(Oversikt!$B$23="J",1,0)
A30: Kueiningar – Geit | B30: Utrekna | C30: =Geit!C55*IF(Oversikt!$B$24="J",1,0) | D30: stk | E30: Kueiningar – Geit = «Kueiningar» [Geit!C55] × Med i totalen Geit [Oversikt!B24 → 1/0] | F30: =Geit!C55*IF(Oversikt!$B$24="J",1,0)
A31: Sum «kueiningar» | B31: Utrekna | C31: =C25+C26+C27+C28+C29+C30 | D31: stk | E31: Sum «kueiningar» = Kueiningar – Mjølk [C25] + Kueiningar – Oksar [C26] + Kueiningar – Mellomkalv [C27] + Kueiningar – Ammekyr [C28] + Kueiningar – Sau [C29] + Kueiningar – Geit [C30] | F31: =C25+C26+C27+C28+C29+C30
A32: Eigen grovfôrkostnad – Mjølk | B32: Utrekna | C32: ='Mjølk'!C53*IF(Oversikt!$B$16="J",1,0) | D32: kr | E32: Eigen grovfôrkostnad – Mjølk = Sum eigen grovfôrproduksjon (utan lagerendring) [Mjølk!C53] × Med i totalen Mjølk [Oversikt!B16 → 1/0] | F32: ='Mjølk'!C53*IF(Oversikt!$B$16="J",1,0)
A33: Eigen grovfôrkostnad – Oksar | B33: Utrekna | C33: =Oksar!C50*IF(Oversikt!$B$17="J",1,0) | D33: kr | E33: Eigen grovfôrkostnad – Oksar = Sum eigen grovfôrproduksjon (utan lagerendring) [Oksar!C50] × Med i totalen Oksar [Oversikt!B17 → 1/0] | F33: =Oksar!C50*IF(Oversikt!$B$17="J",1,0)
A34: Eigen grovfôrkostnad – Mellomkalv | B34: Utrekna | C34: =Mellomkalv!C50*IF(Oversikt!$B$18="J",1,0) | D34: kr | E34: Eigen grovfôrkostnad – Mellomkalv = Sum eigen grovfôrproduksjon (utan lagerendring) [Mellomkalv!C50] × Med i totalen Mellomkalv [Oversikt!B18 → 1/0] | F34: =Mellomkalv!C50*IF(Oversikt!$B$18="J",1,0)
A35: Eigen grovfôrkostnad – Ammekyr | B35: Utrekna | C35: =Ammekyr!C55*IF(Oversikt!$B$19="J",1,0) | D35: kr | E35: Eigen grovfôrkostnad – Ammekyr = Sum eigen grovfôrproduksjon (utan lagerendring) [Ammekyr!C55] × Med i totalen Ammekyr [Oversikt!B19 → 1/0] | F35: =Ammekyr!C55*IF(Oversikt!$B$19="J",1,0)
A36: Eigen grovfôrkostnad – Sau | B36: Utrekna | C36: =Sau!C61*IF(Oversikt!$B$23="J",1,0) | D36: kr | E36: Eigen grovfôrkostnad – Sau = Sum eigen grovfôrproduksjon (utan lagerendring) [Sau!C61] × Med i totalen Sau [Oversikt!B23 → 1/0] | F36: =Sau!C61*IF(Oversikt!$B$23="J",1,0)
A37: Eigen grovfôrkostnad – Geit | B37: Utrekna | C37: =Geit!C49*IF(Oversikt!$B$24="J",1,0) | D37: kr | E37: Eigen grovfôrkostnad – Geit = Sum eigen grovfôrproduksjon (utan lagerendring) [Geit!C49] × Med i totalen Geit [Oversikt!B24 → 1/0] | F37: =Geit!C49*IF(Oversikt!$B$24="J",1,0)
A38: Sum eigen grovfôrkostnad (fordelingsnøkkel areal) | B38: Utrekna | C38: =C32+C33+C34+C35+C36+C37 | D38: kr | E38: Sum eigen grovfôrkostnad (fordelingsnøkkel areal) = Eigen grovfôrkostnad – Mjølk [C32] + Eigen grovfôrkostnad – Oksar [C33] + Eigen grovfôrkostnad – Mellomkalv [C34] + Eigen grovfôrkostnad – Ammekyr [C35] + Eigen grovfôrkostnad – Sau [C36] + Eigen grovfôrkostnad – Geit [C37] | F38: =C32+C33+C34+C35+C36+C37
A39: Sum variabel grovfôrkostnad (utan plast) | B39: Utrekna | C39: ='Mjølk'!C52*IF(Oversikt!$B$16="J",1,0)+Oksar!C49*IF(Oversikt!$B$17="J",1,0)+Mellomkalv!C49*IF(Oversikt!$B$18="J",1,0)+Ammekyr!C54*IF(Oversikt!$B$19="J",1,0)+Sau!C60*IF(Oversikt!$B$23="J",1,0)+Geit!C48*IF(Oversikt!$B$24="J",1,0) | D39: kr | E39: Sum variabel grovfôrkostnad (utan plast) = Variabel grovfôrkostnad (utan plast og lagerendring eigenprodusert) [Mjølk!C52] × Med i totalen Mjølk [Oversikt!B16 → 1/0] + Variabel grovfôrkostnad (utan plast og lagerendring eigenprodusert) [Oksar!C49] × Med i totalen Oksar [Oversikt!B17 → 1/0] + Variabel grovfôrkostnad (utan plast og lagerendring eigenprodusert) [Mellomkalv!C49] × Med i totalen Mellomkalv [Oversikt!B18 → 1/0] + Variabel grovfôrkostnad (utan plast og lagerendring eigenprodusert) [Ammekyr!C54] × Med i totalen Ammekyr [Oversikt!B19 → 1/0] + Variabel grovfôrkostnad (utan plast og lagerendring eigenprodusert) [Sau!C60] × Med i totalen Sau [Oversikt!B23 → 1/0] + Variabel grovfôrkostnad (utan plast og lagerendring eigenprodusert) [Geit!C48] × Med i totalen Geit [Oversikt!B24 → 1/0] | F39: ='Mjølk'!C52*IF(Oversikt!$B$16="J",1,0)+Oksar!C49*IF(Oversikt!$B$17="J",1,0)+Mellomkalv!C49*IF(Oversikt!$B$18="J",1,0)+Ammekyr!C54*IF(Oversikt!$B$19="J",1,0)+Sau!C60*IF(Oversikt!$B$23="J",1,0)+Geit!C48*IF(Oversikt!$B$24="J",1,0)
A40: Maskinkostnader i grovfôrproduksjonane | B40: Utrekna | C40: ='Faste kostnader'!C46*IF(Oversikt!$B$16="J",1,0)+'Faste kostnader'!C47*IF(Oversikt!$B$17="J",1,0)+'Faste kostnader'!C48*IF(Oversikt!$B$18="J",1,0)+'Faste kostnader'!C49*IF(Oversikt!$B$19="J",1,0)+'Faste kostnader'!C53*IF(Oversikt!$B$23="J",1,0)+'Faste kostnader'!C54*IF(Oversikt!$B$24="J",1,0) | D40: kr | E40: Maskinkostnader i grovfôrproduksjonane = Maskinkostnader – Mjølk [Faste kostnader!C46] × Med i totalen Mjølk [Oversikt!B16 → 1/0] + Maskinkostnader – Oksar [Faste kostnader!C47] × Med i totalen Oksar [Oversikt!B17 → 1/0] + Maskinkostnader – Mellomkalv [Faste kostnader!C48] × Med i totalen Mellomkalv [Oversikt!B18 → 1/0] + Maskinkostnader – Ammekyr [Faste kostnader!C49] × Med i totalen Ammekyr [Oversikt!B19 → 1/0] + Maskinkostnader – Sau [Faste kostnader!C53] × Med i totalen Sau [Oversikt!B23 → 1/0] + Maskinkostnader – Geit [Faste kostnader!C54] × Med i totalen Geit [Oversikt!B24 → 1/0] | F40: ='Faste kostnader'!C46*IF(Oversikt!$B$16="J",1,0)+'Faste kostnader'!C47*IF(Oversikt!$B$17="J",1,0)+'Faste kostnader'!C48*IF(Oversikt!$B$18="J",1,0)+'Faste kostnader'!C49*IF(Oversikt!$B$19="J",1,0)+'Faste kostnader'!C53*IF(Oversikt!$B$23="J",1,0)+'Faste kostnader'!C54*IF(Oversikt!$B$24="J",1,0)
A41: DB grovfôrbaserte husdyr u/tilskot | B41: Utrekna | C41: ='Mjølk'!C56*IF(Oversikt!$B$16="J",1,0)+Oksar!C53*IF(Oversikt!$B$17="J",1,0)+Mellomkalv!C53*IF(Oversikt!$B$18="J",1,0)+Ammekyr!C58*IF(Oversikt!$B$19="J",1,0)+Sau!C64*IF(Oversikt!$B$23="J",1,0)+Geit!C52*IF(Oversikt!$B$24="J",1,0) | D41: kr | E41: DB grovfôrbaserte husdyr u/tilskot = Dekningsbidrag (DB) utan tilskot [Mjølk!C56] × Med i totalen Mjølk [Oversikt!B16 → 1/0] + Dekningsbidrag (DB) utan tilskot [Oksar!C53] × Med i totalen Oksar [Oversikt!B17 → 1/0] + Dekningsbidrag (DB) utan tilskot [Mellomkalv!C53] × Med i totalen Mellomkalv [Oversikt!B18 → 1/0] + Dekningsbidrag (DB) utan tilskot [Ammekyr!C58] × Med i totalen Ammekyr [Oversikt!B19 → 1/0] + Dekningsbidrag (DB) utan tilskot [Sau!C64] × Med i totalen Sau [Oversikt!B23 → 1/0] + Dekningsbidrag (DB) utan tilskot [Geit!C52] × Med i totalen Geit [Oversikt!B24 → 1/0] | F41: ='Mjølk'!C56*IF(Oversikt!$B$16="J",1,0)+Oksar!C53*IF(Oversikt!$B$17="J",1,0)+Mellomkalv!C53*IF(Oversikt!$B$18="J",1,0)+Ammekyr!C58*IF(Oversikt!$B$19="J",1,0)+Sau!C64*IF(Oversikt!$B$23="J",1,0)+Geit!C52*IF(Oversikt!$B$24="J",1,0)
...

Sheet Korn
A1: Kornproduksjon – driftsgrein 1100-1190
A2: Korn til modning (driftsgrein 1100–1190).
A3: Fargekodar: blå tal på gul botn = input (skal fyllast inn) · svart = formel · grøn = lenkje frå anna ark. Alle kronebeløp er positive (inntekt og kostnad).
A5: Post | B5: Kjelde / Tripletex-konto | C5: Verdi | D5: Eining | E5: Formel forklart (korleis outputen blir rekna) | F5: Excel-formel
A6: 1. INPUT – Produksjonsdata
A7: Tal dekar | B7: Produksjonstabell / søknad om produksjonstilskot | C7: 60 | D7: da | E7: Input. Hentast frå: Produksjonstabell / søknad om produksjonstilskot.
A8: Avling totalt | B8: Produksjonstabell / avlingsregistrering | C8: 24000 | D8: kg | E8: Input. Hentast frå: Produksjonstabell / avlingsregistrering.
A9: Seld mengd | B9: Mengde 1/2 på salskonto (3000-3007) | C9: 20000 | D9: kg | E9: Input. Hentast frå: Mengde 1/2 på salskonto (3000-3007).
A10: 2. INPUT – Rekneskapstal (kr) frå saldobalansen etter korrigeringar
A11: Produksjonstilskot fordelt på produksjonen | B11: 34xx (ikkje 344x avløysartilskot) | C11: 42000 | D11: kr | E11: Input. Hentast frå: 34xx (ikkje 344x avløysartilskot).
A12: Sal av korn | B12: 3000-3007 | C12: 72000 | D12: kr | E12: Input. Hentast frå: 3000-3007.
A13: Sal av halm | B13: 3096 | C13: 6000 | D13: kr | E13: Input. Hentast frå: 3096.
A14: Beholdningsendring ferdigvarer (+ = auke) | B14: 4290-4298 (forteikn snudd) | C14: 3000 | D14: kr | E14: Input. Hentast frå: 4290-4298 (forteikn snudd).
A15: Andre inntekter | B15: andre 3xxx kopla til produksjonen | C15: 0 | D15: kr | E15: Input. Hentast frå: andre 3xxx kopla til produksjonen.
A16: Variable kostnader
A17: Gjødsel og kalk | B17: 4050, 4057, 4095 | C17: 27000 | D17: kr | E17: Input. Hentast frå: 4050, 4057, 4095.
A18: Plantevernmiddel | B18: 4110, 4111, 4191 | C18: 9000 | D18: kr | E18: Input. Hentast frå: 4110, 4111, 4191.
A19: Såkorn | B19: 4000 | C19: 15000 | D19: kr | E19: Input. Hentast frå: 4000.
A20: Andre variable kostnader | B20: 4540-4549, 4160 + andre 4xxx | C20: 8000 | D20: kr | E20: Input. Hentast frå: 4540-4549, 4160 + andre 4xxx.
A21: 3. INPUT – Fordelte faste kostnader (lenka frå arket «Faste kostnader»)
A22: Maskinkostnader fordelt | B22: Lenkje frå anna ark | C22: ='Faste kostnader'!C37 | D22: kr | E22: Maskinkostnader fordelt = Maskinkostnader – Korn [Faste kostnader!C37] | F22: ='Faste kostnader'!C37
A23: 4. UTREKNING – Totalt for produksjonen
A24: Produksjonsinntekter i alt | B24: Utrekna | C24: =C12+C13+C14+C15 | D24: kr | E24: Produksjonsinntekter i alt = Sal av korn [C12] + Sal av halm [C13] + Beholdningsendring ferdigvarer (+ = auke) [C14] + Andre inntekter [C15] | F24: =C12+C13+C14+C15
A25: Variable kostnader i alt | B25: Utrekna | C25: =C17+C18+C19+C20 | D25: kr | E25: Variable kostnader i alt = Gjødsel og kalk [C17] + Plantevernmiddel [C18] + Såkorn [C19] + Andre variable kostnader [C20] | F25: =C17+C18+C19+C20
A26: Dekningsbidrag (DB) utan tilskot | B26: Utrekna | C26: =C24-C25 | D26: kr | E26: Dekningsbidrag (DB) utan tilskot = Produksjonsinntekter i alt [C24] − Variable kostnader i alt [C25] | F26: =C24-C25
A27: Dekningsbidrag (DB) med tilskot | B27: Utrekna | C27: =C26+C11 | D27: kr | E27: Dekningsbidrag (DB) med tilskot = Dekningsbidrag (DB) utan tilskot [C26] + Produksjonstilskot fordelt på produksjonen [C11] | F27: =C26+C11
A28: DB m/tilskot etter maskinkostnader | B28: Utrekna | C28: =C27-C22 | D28: kr | E28: DB m/tilskot etter maskinkostnader = Dekningsbidrag (DB) med tilskot [C27] − Maskinkostnader fordelt [C22] | F28: =C27-C22
A29: 5. OUTPUT – Per eining (pr dekar)
A30: Produksjonsinntekter pr dekar
A31: Sal av korn | B31: Utrekna | C31: =IF((C7)=0,0,(C12)/(C7)) | D31: kr | E31: Sal av korn = Sal av korn [C12] ÷ Tal dekar [C7] | F31: =IF((C7)=0,0,(C12)/(C7))
A32: Sal av halm | B32: Utrekna | C32: =IF((C7)=0,0,(C13)/(C7)) | D32: kr | E32: Sal av halm = Sal av halm [C13] ÷ Tal dekar [C7] | F32: =IF((C7)=0,0,(C13)/(C7))
A33: Beholdningsendring ferdigvarer (+ = auke) | B33: Utrekna | C33: =IF((C7)=0,0,(C14)/(C7)) | D33: kr | E33: Beholdningsendring ferdigvarer (+ = auke) = Beholdningsendring ferdigvarer (+ = auke) [C14] ÷ Tal dekar [C7] | F33: =IF((C7)=0,0,(C14)/(C7))
A34: Andre inntekter | B34: Utrekna | C34: =IF((C7)=0,0,(C15)/(C7)) | D34: kr | E34: Andre inntekter = Andre inntekter [C15] ÷ Tal dekar [C7] | F34: =IF((C7)=0,0,(C15)/(C7))
A35: Produksjonsinntekter i alt | B35: Utrekna | C35: =IF((C7)=0,0,(C24)/(C7)) | D35: kr | E35: Produksjonsinntekter i alt = Produksjonsinntekter i alt [C24] ÷ Tal dekar [C7] | F35: =IF((C7)=0,0,(C24)/(C7))
A36: Variable kostnader pr dekar
A37: Gjødsel og kalk | B37: Utrekna | C37: =IF((C7)=0,0,(C17)/(C7)) | D37: kr | E37: Gjødsel og kalk = Gjødsel og kalk [C17] ÷ Tal dekar [C7] | F37: =IF((C7)=0,0,(C17)/(C7))
A38: Plantevernmiddel | B38: Utrekna | C38: =IF((C7)=0,0,(C18)/(C7)) | D38: kr | E38: Plantevernmiddel = Plantevernmiddel [C18] ÷ Tal dekar [C7] | F38: =IF((C7)=0,0,(C18)/(C7))
A39: Såkorn | B39: Utrekna | C39: =IF((C7)=0,0,(C19)/(C7)) | D39: kr | E39: Såkorn = Såkorn [C19] ÷ Tal dekar [C7] | F39: =IF((C7)=0,0,(C19)/(C7))
A40: Andre variable kostnader | B40: Utrekna | C40: =IF((C7)=0,0,(C20)/(C7)) | D40: kr | E40: Andre variable kostnader = Andre variable kostnader [C20] ÷ Tal dekar [C7] | F40: =IF((C7)=0,0,(C20)/(C7))
A41: Sum variable kostnader | B41: Utrekna | C41: =IF((C7)=0,0,(C25)/(C7)) | D41: kr | E41: Sum variable kostnader = Variable kostnader i alt [C25] ÷ Tal dekar [C7] | F41: =IF((C7)=0,0,(C25)/(C7))
...

Sheet Silofor
A1: Sal av silofôr / rundballar – driftsgrein 1522-1523
A2: Areal der graset blir selt som silofôr/rundballar (driftsgrein 1522–1523). Eksempeltal frå vedlagt analyse 2025.
A3: Fargekodar: blå tal på gul botn = input (skal fyllast inn) · svart = formel · grøn = lenkje frå anna ark. Alle kronebeløp er positive (inntekt og kostnad).
A5: Post | B5: Kjelde / Tripletex-konto | C5: Verdi | D5: Eining | E5: Formel forklart (korleis outputen blir rekna) | F5: Excel-formel
A6: 1. INPUT – Produksjonsdata
A7: Tal dekar | B7: Produksjonstabell / søknad om produksjonstilskot | C7: 50 | D7: da | E7: Input. Hentast frå: Produksjonstabell / søknad om produksjonstilskot.
A8: Avling totalt | B8: Produksjonstabell / avlingsregistrering | C8: 0 | D8: kg | E8: Input. Hentast frå: Produksjonstabell / avlingsregistrering.
A9: Seld mengd | B9: Mengde 1/2 på salskonto (3095) | C9: 0 | D9: kg | E9: Input. Hentast frå: Mengde 1/2 på salskonto (3095).
A10: Tal siloballar seld | B10: Mengde 1 på konto 3095 | C10: 253 | D10: stk | E10: Input. Hentast frå: Mengde 1 på konto 3095.
A11: Auke i varelager (kg) | B11: Mengde på konto 4297/1447 (.472) | C11: 0 | D11: kg | E11: Input. Hentast frå: Mengde på konto 4297/1447 (.472).
A12: 2. INPUT – Rekneskapstal (kr) frå saldobalansen etter korrigeringar
A13: Produksjonstilskot fordelt på produksjonen | B13: 34xx (ikkje 344x avløysartilskot) | C13: 28980.38 | D13: kr | E13: Input. Hentast frå: 34xx (ikkje 344x avløysartilskot).
A14: Sal av silofôr | B14: 3095 | C14: 206400 | D14: kr | E14: Input. Hentast frå: 3095.
A15: Beholdningsendring ferdigvarer (+ = auke) | B15: 4290-4298 (forteikn snudd) | C15: -15000 | D15: kr | E15: Input. Hentast frå: 4290-4298 (forteikn snudd).
A16: Andre inntekter | B16: andre 3xxx kopla til produksjonen | C16: 0 | D16: kr | E16: Input. Hentast frå: andre 3xxx kopla til produksjonen.
A17: Variable kostnader
A18: Gjødsel og kalk | B18: 4050, 4057, 4095 | C18: 21666.4 | D18: kr | E18: Input. Hentast frå: 4050, 4057, 4095.
A19: Plantevernmiddel | B19: 4110, 4111, 4191 | C19: 1223.77 | D19: kr | E19: Input. Hentast frå: 4110, 4111, 4191.
A20: Grasfrø | B20: 4001 | C20: 4021 | D20: kr | E20: Input. Hentast frå: 4001.
A21: Andre variable kostnader | B21: 4540-4549, 4160 + andre 4xxx | C21: 15758.5 | D21: kr | E21: Input. Hentast frå: 4540-4549, 4160 + andre 4xxx.
A22: 3. INPUT – Fordelte faste kostnader (lenka frå arket «Faste kostnader»)
A23: Maskinkostnader fordelt | B23: Lenkje frå anna ark | C23: ='Faste kostnader'!C38 | D23: kr | E23: Maskinkostnader fordelt = Maskinkostnader – Silofor [Faste kostnader!C38] | F23: ='Faste kostnader'!C38
A24: 4. UTREKNING – Totalt for produksjonen
A25: Produksjonsinntekter i alt | B25: Utrekna | C25: =C14+C15+C16 | D25: kr | E25: Produksjonsinntekter i alt = Sal av silofôr [C14] + Beholdningsendring ferdigvarer (+ = auke) [C15] + Andre inntekter [C16] | F25: =C14+C15+C16
A26: Variable kostnader i alt | B26: Utrekna | C26: =C18+C19+C20+C21 | D26: kr | E26: Variable kostnader i alt = Gjødsel og kalk [C18] + Plantevernmiddel [C19] + Grasfrø [C20] + Andre variable kostnader [C21] | F26: =C18+C19+C20+C21
A27: Dekningsbidrag (DB) utan tilskot | B27: Utrekna | C27: =C25-C26 | D27: kr | E27: Dekningsbidrag (DB) utan tilskot = Produksjonsinntekter i alt [C25] − Variable kostnader i alt [C26] | F27: =C25-C26
A28: Dekningsbidrag (DB) med tilskot | B28: Utrekna | C28: =C27+C13 | D28: kr | E28: Dekningsbidrag (DB) med tilskot = Dekningsbidrag (DB) utan tilskot [C27] + Produksjonstilskot fordelt på produksjonen [C13] | F28: =C27+C13
A29: DB m/tilskot etter maskinkostnader | B29: Utrekna | C29: =C28-C23 | D29: kr | E29: DB m/tilskot etter maskinkostnader = Dekningsbidrag (DB) med tilskot [C28] − Maskinkostnader fordelt [C23] | F29: =C28-C23
A30: 5. OUTPUT – Per eining (pr dekar)
A31: Produksjonsinntekter pr dekar
A32: Sal av silofôr | B32: Utrekna | C32: =IF((C7)=0,0,(C14)/(C7)) | D32: kr | E32: Sal av silofôr = Sal av silofôr [C14] ÷ Tal dekar [C7] | F32: =IF((C7)=0,0,(C14)/(C7))
A33: Beholdningsendring ferdigvarer (+ = auke) | B33: Utrekna | C33: =IF((C7)=0,0,(C15)/(C7)) | D33: kr | E33: Beholdningsendring ferdigvarer (+ = auke) = Beholdningsendring ferdigvarer (+ = auke) [C15] ÷ Tal dekar [C7] | F33: =IF((C7)=0,0,(C15)/(C7))
A34: Andre inntekter | B34: Utrekna | C34: =IF((C7)=0,0,(C16)/(C7)) | D34: kr | E34: Andre inntekter = Andre inntekter [C16] ÷ Tal dekar [C7] | F34: =IF((C7)=0,0,(C16)/(C7))
A35: Produksjonsinntekter i alt | B35: Utrekna | C35: =IF((C7)=0,0,(C25)/(C7)) | D35: kr | E35: Produksjonsinntekter i alt = Produksjonsinntekter i alt [C25] ÷ Tal dekar [C7] | F35: =IF((C7)=0,0,(C25)/(C7))
A36: Variable kostnader pr dekar
A37: Gjødsel og kalk | B37: Utrekna | C37: =IF((C7)=0,0,(C18)/(C7)) | D37: kr | E37: Gjødsel og kalk = Gjødsel og kalk [C18] ÷ Tal dekar [C7] | F37: =IF((C7)=0,0,(C18)/(C7))
A38: Plantevernmiddel | B38: Utrekna | C38: =IF((C7)=0,0,(C19)/(C7)) | D38: kr | E38: Plantevernmiddel = Plantevernmiddel [C19] ÷ Tal dekar [C7] | F38: =IF((C7)=0,0,(C19)/(C7))
A39: Grasfrø | B39: Utrekna | C39: =IF((C7)=0,0,(C20)/(C7)) | D39: kr | E39: Grasfrø = Grasfrø [C20] ÷ Tal dekar [C7] | F39: =IF((C7)=0,0,(C20)/(C7))
